
<mujoco model="bittle_simple">

    <compiler balanceinertia="true" angle="radian"/>


    <option timestep="0.001" iterations="50" tolerance="1e-10" solver="Newton" integrator="Euler" jacobian="auto" cone="pyramidal"  />

    <visual>
        <map force="0.1" zfar="30"/>
        <rgba haze="0.15 0.25 0.35 1"/>
        <quality shadowsize="2048"/>
        <global offwidth="800" offheight="800"/>
    </visual>

    <asset>
        <texture type="skybox" builtin="gradient" rgb1="0.3 0.5 0.7" rgb2="0 0 0" width="512" height="512"/>
        <texture name="texplane" type="2d" builtin="checker" rgb1=".2 .3 .4" rgb2=".1 0.15 0.2" width="512" height="512" mark="cross" markrgb=".8 .8 .8"/>
        <texture name="texgeom" type="cube" builtin="flat" mark="cross" width="127" height="1278"
            rgb1="0.8 0.6 0.4" rgb2="0.8 0.6 0.4" markrgb="1 1 1" random="0.01"/>
        <material name="matplane" reflectance="0.3" texture="texplane" texrepeat="1 1" texuniform="true"/>
        <material name="matgeom" texture="texgeom" texuniform="true" rgba="0.8 0.6 .4 1"/>
    </asset>

    <worldbody>
        <geom name="floor" pos="0 0 0" size="0 0 .5" type="plane" material="matplane" condim="4" friction="1 0.01 0.001"/>

        <body name="torso" pos="0 0 0.11">
            <inertial mass = "20" diaginertia="0.026963333333333335 0.013581666666666667 0.04038166666666667" pos="0 0 0"/>

            <freejoint name="root"/>
            <geom conaffinity="1" contype="1" name="torso"  type="box" size="0.045 0.0635 0.0035" pos="0 0 0"/>

            <body name="lfs" pos="-0.0485 0.0735 0" >
                <inertial mass = "0.6" diaginertia="1.3000000000000003e-04 7.450000000000001e-06 1.2745000000000002e-04" pos="0 0 0" />
                <geom name="lfs" conaffinity="0" contype="0" type="box" size="0.0035 0.025 0.005" />
                <joint name="lfsj" type="hinge" pos="0 -0.023 0" axis="1 0 0" range="-6.28 6.28" damping="0.5"/>

                <body name="lfk" pos="0.0075 0.04725 0" >
                    <inertial mass = "1.7" diaginertia="5.241666666666667e-04 2.8333333333333336e-05 5.241666666666667e-04" pos="0 0 0"/>
                    <geom name="lfk" type="capsule" size="0.005 0.0275 " zaxis = "0 1 0" condim="4" friction="1 0.01 0.001"/>
                    <joint name="lfkj" type="hinge" pos="0 -0.02425 0" axis="1 0 0" range="-6.28 6.28" damping="0.5"/>
                </body>
            </body>

            <body name="rfs" pos="0.0485 0.0735 0" >
                <inertial mass = "0.6" diaginertia="1.3000000000000003e-04 7.450000000000001e-06 1.2745000000000002e-04" pos="0 0 0" />
                <geom name="rfs" conaffinity="0" contype="0" type="box" size="0.0035 0.025 0.005" />
                <joint name="rfsj" type="hinge" pos="0 -0.023 0" axis="1 0 0" range="-6.28 6.28" damping="0.5"/>

                <body name="rfk" pos="-0.0075 0.04725 0" >
                    <inertial mass = "1.7" diaginertia="5.241666666666667e-04 2.8333333333333336e-05 5.241666666666667e-04" pos="0 0 0"/>
                    <geom name="rfk" type="capsule" size="0.005 0.0275 " zaxis = "0 1 0" condim="4" friction="1 0.01 0.001"/>
                    <joint name="rfkj" type="hinge" pos="0 -0.02425 0" axis="1 0 0" range="-6.28 6.28" damping="0.5"/>
                </body>
            </body>

            <body name="lbs" pos="-0.0485 -0.0735 0" >
                <inertial mass = "0.6" diaginertia="1.3000000000000003e-04 7.450000000000001e-06 1.2745000000000002e-04" pos="0 0 0" />
                <geom name="lbs" conaffinity="0" contype="0" type="box" size="0.0035 0.025 0.005" />
                <joint name="lbsj" type="hinge" pos="0 0.023 0" axis="1 0 0" range="-6.28 6.28" damping="0.5"/>

                <body name="lbk" pos="0.0075 -0.04725 0" >
                    <inertial mass = "1.7" diaginertia="5.241666666666667e-04 2.8333333333333336e-05 5.241666666666667e-04" pos="0 0 0"/>
                    <geom name="lbk" type="capsule" size="0.005 0.0275 " zaxis = "0 1 0" condim="4" friction="1 0.01 0.001"/>
                    <joint name="lbkj" type="hinge" pos="0 0.02425 0" axis="1 0 0" range="-6.28 6.28" damping="0.5"/>
                </body>
            </body>

             <body name="rbs" pos="0.0485 -0.0735 0" >
                <inertial mass = "0.6" diaginertia="1.3000000000000003e-04 7.450000000000001e-06 1.2745000000000002e-04" pos="0 0 0" />
                <geom name="rbs" conaffinity="0" contype="0" type="box" size="0.0035 0.025 0.005" />
                <joint name="rbsj" type="hinge" pos="0 0.023 0" axis="1 0 0" range="-6.28 6.28" damping="0.5"/>

                <body name="rbk" pos="-0.0075 -0.04725 0" >
                    <inertial mass = "1.7" diaginertia="5.241666666666667e-04 2.8333333333333336e-05 5.241666666666667e-04" pos="0 0 0"/>
                    <geom name="rbk" type="capsule" size="0.005 0.0275 " zaxis = "0 1 0" condim="4" friction="1 0.01 0.001"/>
                    <joint name="rbkj" type="hinge" pos="0 0.02425 0" axis="1 0 0" range="-6.28 6.28" damping="0.5"/>
                </body>
            </body>



        </body>
    </worldbody>

<!--     <actuator>
        <position name = "lfs_K" kp = "150" joint = "lfsj"  />
        <position name = "lfk_K" kp = "150" joint = "lfkj"  />

        <position name = "rfs_K" kp = "150" joint = "rfsj"  />
        <position name = "rfk_K" kp = "150" joint = "rfkj"  />

        <position name = "lbs_K" kp = "150" joint = "lbsj"  />
        <position name = "lbk_K" kp = "150" joint = "lbkj"  />

        <position name = "rbs_K" kp = "150" joint = "rbsj"  />
        <position name = "rbk_K" kp = "150" joint = "rbkj"  />





        <velocity name = "lfs_D" kv = "0.02" joint = "lfsj"/>
        <velocity name = "lfk_D" kv = "0.02" joint = "lfkj"/>


        <velocity name = "rfs_D" kv = "0.02" joint = "rfsj"/>
        <velocity name = "rfk_D" kv = "0.02" joint = "rfkj"/>

        <velocity name = "lbs_D" kv = "0.02" joint = "lbsj"/>
        <velocity name = "lbk_D" kv = "0.02" joint = "lbkj"/>

        <velocity name = "rbs_D" kv = "0.02" joint = "rbsj"/>
        <velocity name = "rbk_D" kv = "0.02" joint = "rbkj"/>

    </actuator> -->



</mujoco>
